Workbook

Sheet OVERVIEW
B3: Description and Guide to the RNG (Renewable Natural Gas) Database
B5: A. PURPOSE
B7: The RNG database was developed to provide a comprehensive list of biogas projects that are upgrading gas for pipeline injection or use as vehicle fuel (whether locally or at the end of a pipeline).
B8: It includes projects that are known to have been in operation or under construction prior to December 31, 2023, along with previously operational projects now shut down.
B9: It also includes projects that are projected to be under construction or operational by December 31, 2023.
B10: Because the size and scope of projects that do not have a “shovel in the ground” are often in flux, the database excludes planned projects.
B11: The database is an Excel.xls format spreadsheet and is compatible with any version of Misrosoft Excel. Although a handful of Canadian projects deliver RNG into the US, all projects listed in the database are in the United States.
B13: B. ACKNOWLEDGEMENTS
B15: This spreadsheet was developed by staff of Argonne National Laboratory ("Argonne") and Energy Vision. Argonne is a U.S. Department of Energy laboratory managed by UChicago Argonne, LLC under contract DE-AC02-06CH11357. | S15: DE-AC02-06CH11357.
B16: Energy Vision is a 501 (c)(3) environmental research group. Energy Vision’s work was conducted under Argonne Contract No. 0F-60161.
B17: This spreadsheet was prepared as an account of work sponsored by an agency of the United States Government. Neither the United States Government nor any agency thereof, nor UChicago Argonne, LLC, nor any of their employees or officers,
B18: makes any warranty, express or implied, or assumes any legal liability or responsibility for the accuracy, completeness, or usefulness of any information, apparatus, product, or process disclosed, or represents that its use would not infringe privately owned rights.
B19: Reference herein to any specific commercial product, process, or service by trade name, trademark, manufacturer, or otherwise, does not necessarily constitute or imply its endorsement, recommendation, or favoring by the United States Government
B20: or any agency thereof. The views and opinions of document authors expressed herein do not necessarily state or reflect those of the United States Government or any agency thereof, Argonne National Laboratory, or UChicago Argonne, LLC.
B22: C. STRUCTURE AND DEFINITION OF TERMS
B24: This workook updates earlier work by Argonne and Energy Vision. It focuses on revising the operational status (operational, under construction, planned, cancelled/shut down) of previously documented projects.
B25: Updates are based primarily on press accounts and other public information. Outreach to project contacts was conducted primarily when other sources of information were unavailable or inconclusive.
B28: Excluding this Overview tab, the workbook contains eight tabs: four tabs summarizing projects by feedstock, and four tabs providing summaries, definitions and other notes.
B30: Projects tabs: List RNG projects by the feedstock from which they derive biogas.
B32: 1. Food waste: Projects using commercial or post-consumer food waste as the main feedstock.
B34: 2. Landfills: Projects collecting and upgrading gas from existing landfills.
... B71: F. DATABASE HIGHLIGHTS FOR RNG PROJECTS FULLY OR PARTIALLY GOING TO TRANSPORTATION (PROJECTED AS OF 12/31/23)
B73: · Total projects, all statuses: | F73: =TOTALS!E22 -> 541 | G73: (excluding shut down, canceled, suspended)
B74: · Total confirmed operational projects: | F74: =TOTALS!B22 -> 305
B75: · Total operational production: | F75: =TOTALS!C45 -> 1.0843954e+08 | G75: MMBTU, | H75: =TOTALS!D45 -> 9.6653599e+08 | I75: GGEs or | J75: =TOTALS!E45 -> 8.4266433e+08 | K75: DGEs, up | L75: =TOTALS!C47 -> 0.22034197 | M75: from 12/31/2022
B76: · Total under construction production: | F76: =TOTALS!C58 -> 35494780 | G76: MMBTU, | H76: =TOTALS!D58 -> 3.1636968e+08 | I76: GGEs or | J76: =TOTALS!E58 -> 2.7579464e+08 | K76: DGEs, up | L76: =TOTALS!C60 -> 0.7426933 | M76: from 12/31/2022
B80: G. CITATION AND CONTACT INFORMATION
B82: The spreadsheet may be cited as follows:
B83: Mintz, M. and Lerner, M.. Database of Renewable Natural Gas (RNG) Projects: 2023 Update, Argonne National Laboratory, July 2024, https://www.anl.gov/es/reference/renewable-natural-gas-database.
B85: For further information, please contact:
B86: Marianne Mintz | D86: mmintz@anl.gov | F86: or
B87: Matt Tomich | D87: Tomich@energy-vision.org

Sheet Food Waste
A1: Key: | B1: Project added 2023 | F1: Color coding generally applies to numeric values only.
B2: Information provided or confirmed by contact | F2: Individual values are often drawn from different sources, and so may appear inconsistent-- e.g., gas going for upgrading may be more than total amount of gas collected
B3: Value calculated based on other info provided
B4: Value from press/website
A6: GENERAL INFORMATION | F6: PROJECT INFORMATION | J6: INPUTS | N6: OUTPUTS | V6: ADDITIONAL INFORMATION
A7: Waste Conversion Facility Name | B7: Projected status 12/31/2023 | C7: Facility Owner | D7: County | E7: State | F7: Project Start Date | G7: Project Developer | H7: Project Description | I7: Digester Type | J7: Amount of Waste Delivered | K7: Capacity (tons per day) | L7: Waste Type | M7: Waste Provider | N7: Raw Biogas Produced, SCFD | O7: Upgraded SCFD | P7: Upgraded MMBTU/yr. | Q7: Upgraded Fuel Type Produced | R7: If producing vehicle fuel, public filling station? | S7: GGE/yr. | T7: Capacity (GGE/yr.) | U7: Electricity Produced | V7: Annual CO2 Emissions Eliminated | X7: RIN Registrant? | Y7: References
A8: OPERATIONAL AS OF 12/31/2023
A9: Blue Line Biogenic CNG Facility | B9: OPERATIONAL | D9: San Francisco | E9: CA | F9: 2015 | G9: Blue Line Transfer, Inc.; Zero Waste Energy, LLC; South San Francisco Scavenger Co. | H9: Converts food and green waste into CNG fuel for 27 vehicles, during the weekdays they use a mix of CNG and NG, on the weekends when they have more fill time they use all CNG. Appears to be activated carbon upgrading system. | I9: 8 dry anaerobic digesters, thermophilic | J9: 11,200 tons/yr. | K9: 11200 tons/year | L9: Commercial and residential organics | M9: Customer base | N9: 73300 | O9: =N9*0.6 -> 43980 | P9: =O9*0.001*365*0.9 -> 14447.43 | Q9: VEHICLE FUEL (LOCAL) | R9: Private | S9: =P9/0.112194 -> 128771.86 | U9: N/A | X9: Yes | Y9: http://www.americanbiogascouncil.org/projectprofiles/southsanfranciscoca.pdf http://zerowasteenergy.com/our-projects/blue-line-biogenic-cng-facility/ https://www.biocycle.net/2016/07/14/biogas-fleet-fuel-south-san-francisco/ https://energy-vision.org/wp-content/uploads/2016/01/South-SF-Scavenger-BlueLine-Profile.pdf https://www.biocycle.net/second-food-scraps-to-rng-project-certified-under-california-lcfs-greet-3-0/ https://www.greencarcongress.com/2021/03/20210309-ssfsc.html
A10: CR&R Perris Transfer Station and MRF | B10: OPERATIONAL | C10: CR&R | D10: Riverside | E10: CA | F10: 2016 | G10: CR&R Waste and Recycling Services | H10: Will create high BTU RNG derived from MSW using two state anaerobic digestion; CNG fueling station is currently fueling 320 of CR&R's collection vehicles, eventually to be expanded to 900. Excess CNG will feed into a natural gas pipeline distribution system; digestate will be utilized as a soil amendment | I10: Eisenmann mixed plug flow. Upgrading technology Greenlane Biogas (water wash) | J10: As of 2021, with phases 1 & 2 complete, they are accepting about 100,000 tons per year. | K10: With phase 2 complete, approx. 470 tpd. With competion of phase 4, this will increase to ~900 tpd | L10: Commercial food scraps, green waste, FOG. | M10: Customer base | N10: =O10/0.6 -> 569223.74 | O10: =P10/(0.001*365*0.9) -> 341534.25 | P10: =S10*0.112194 -> 112194 | Q10: BOTH | R10: No | S10: 1000000 | T10: 4,000,000 GGE by 2021 | U10: N/A | V10: =11548*2 -> 23096 | X10: Yes | Y10: http://biomassmagazine.com/articles/10641/crr-breaks-ground-on-california-ad-facility http://www.prnewswire.com/news-releases/socalgas-and-crr-environmental-announce-construction-of-pipeline-to-provide-carbon-neutral-renewable-natural-gas-300399808.html http://www.fleetsandfuels.com/fuels/cng/2017/02/sogalgas-and-crr-for-rng-pipeline/ http://crrwasteservices.com/sustainability/anaerobic-digestion/
A11: Escondido Disposal RNG | B11: OPERATIONAL | C11: Escondido Disposal, Inc. | D11: San Diego | E11: CA | F11: Project expected to become operational Q3/Q4 2021 | G11: Escondido Disposal Inc., Hitachi Zoven Innova | H11: EDI will use RNG produced from area food waste to fuel its fleet. As of July one digester is up and running, on tail end of commissioning, have to Cx second. This is potentially a two phase project, with 2 more digesters being installed if EDI's flow increases enough to justify it. | I11: Dry thermophilic, plug flow | J11: ~250 TPD. | L11: Commercial and residential food scraps | M11: Customer base | N11: =O11/0.6 -> 730593.61 | O11: =P11/(0.001*365*0.9) -> 438356.16 | P11: 144000 | Q11: BOTH | R11: Private | S11: =P11/0.112194 -> 1283491.1 | Y11: https://www.times-advocate.com/articles/escondido-ad-facility-is-first-in-county/ https://www.escondidodisposal.com/commercial-waste-services/commercial-services/organic-recycling/# https://dpw.lacounty.gov/epd/tf/Attachments/Minutes_Attachments/2021_Attachments/Hitachi_Zosen_INOVA_Presentation_3-11-2021.pdf https://www.hz-inova.com/renewable-gas/anaerobic-digestion/
A12: Northstate Rendering Anaerobic Digester (formerly Biogas Energy, now Republic Services) | B12: OPERATIONAL | C12: North State Rendering | D12: Butte | E12: CA | F12: 2015 | G12: North State Rendering; Biogas Energy, Inc. | H12: Biogas-to-CNG upgrading produces biomethane that is then compressed and distributed in a CNG fueling station to fuel North State Rendering's truck fleet, which is being converted to duel-fuel CNG/diesel; biomethane is pipeline-quality and can also be injected into the pipeline for sale to other customers (awaiting approval); some biogas pre-upgrading used for combined heat and power generator to produce 100% of the electricity used on site as well as heat to operate the plant. On site fueling facility for vehicles. Update - March 2023 California Energy Commission report has lots of details.- ex. Use of the biogas: • 120-150 standard cubic feet per minute to combined heat and power generator unit to generate 500kW electricity & heat for digesters • 150 standard cubic feet per minute to CNG production to generate 750 DGE per day, or 273,864 DGE per year | J12: 100tpd | K12: Proprietary | L12: Post consumer food waste, FOG, agriculture waste, food processing waste | M12: Residential, commercial, food processors | O12: 108000 | P12: 35478 | Q12: BOTH | R12: Private | S12: 314122 | T12: Proprietary | X12: Unknown | Y12: Feb. 2017 http://www.chicoer.com/article/NA/20170219/NEWS/170219682 https://www.facebook.com/pg/LBGGroupPurchasing/photos/?tab=album&album_id=437696499616003 http://www.biogas-energy.com/site/index.html https://www.landiainc.com/case-studies/north-state-rendering-california https://www.wastetodaymagazine.com/news/republic-services-acquires-anaerobic-digestion-faciloity-california/ https://www.energy.ca.gov/sites/default/files/2023-03/CEC-600-2023-007.pdf
A13: Rialto Bioenergy Facility | B13: OPERATIONAL | C13: Rialto Bioenergy Facility, LLC | D13: San Bernardino | E13: CA | F13: 43435 | G13: Anaergia | H13: Project to begin production in 2020. 700 tpd of food waste and 300 tpd of biosolids. Using Anaergia’s advanced anaerobic digestion technology to extract energy from the organic material, this facility will produce the equivalent of 13 megawatts of clean energy per year. The net carbon dioxide emissions reduction will be approximately 220,000 metric tons annually, which is the equivalent of taking 47,500 cars off the road. Anaergia is building the RBF in collaboration with Waste Management, Republic Services, Southern California Edison, Anaheim Public Utility, Southwest Gas Utility, City of Rialto, the Sanitation Bureau of the City of Los Angeles, and the Sanitation Districts of Los Angeles County, and of Orange County. The RBF is co-funded by the California Energy Commission, U.S. Department of Energy, CalRecycle, State of California and significant private investment. Contact says up to 2.88 MMSCFD upgraded gas injected. Average of 2.02 MMSCFD with onsite power generation. Assuming 2MM SCFD in calculations Pipeline Injection of RNG and onsite power generation for export | I13: Wet Continuously Mixed Anaerobic Digester | J13: 300000 tons per year | K13: 1080 | L13: Food Waste and Biosolids | M13: Waste Management, Republic Services, City of Rialto, Sanitation Districts of LA and Orange Counties | N13: 4.9 MMSCFD | O13: 2000000 | P13: =O13*(0.001*365*0.9) -> 657000 | Q13: PIPELINE (For vehicle/other) | R13: No | S13: =P13/0.112194 -> 5855928.1 | T13: 9.05 Million GGE/year | U13: Up to 4.6 MW | V13: 220,000 MT | X13: Unknown | Y13: https://www.anaergia.com/construction-begins-at-north-america-s-largest-organic-waste-to-energy-facility-anaergia-s-rialto-bioenergy-facility https://www.prnewswire.com/news-releases/first-state-investments-acquires-stake-in-anaergia-services-rialto-bioenergy-facility-301036763.html https://www.kpvi.com/news/national_news/renewable-natural-gas-produced-by-anaergia-from-diverted-landfill-waste-now-flowing-through-socalgas-system/article_569a4bfc-6c96-53d5-a011-ded34bfc2709.html
A14: Archer Daniels Midland corn processing facility | B14: OPERATIONAL | C14: Archer Daniels Midland | D14: Macon | E14: IL | F14: 42856 | G14: Archer Daniels Midland/Ameren Illinois | H14: Renewable natural gas, produced as a byproduct at ADM’s corn processing facility in Decatur, will be distributed by Ameren Illinois into the nation’s natural gas infrastructure. When construction of the project is complete, ADM will purify this methane into pipeline quality natural gas and transport it to an Ameren Illinois’ gas pipeline. Ameren Illinois will then distribute the gas into the interstate pipeline system where it will be available for use as a clean, affordable transportation fuel. ADM will benefit from capitalizing on environmental credits. | L14: Waste from corn processing | M14: Archer Daniels Midland | O14: =P14/(0.001*365*0.9) -> 1155290.7 | P14: 379513 | Q14: PIPELINE (For vehicle/other) | R14: No | S14: Proprietary | T14: Proprietary | X14: Unknown | Y14: https://www.adm.com/news/news-releases/adm-announces-innovative-project-to-provide-renewable-natural-gas http://biomassmagazine.com/articles/14135/biogas-advances-in-the-us http://www.4-traders.com/ARCHER-DANIELS-MIDLAND-CO-11533/news/Archer-Daniels-Midland-ADM-Ameren-partnering-to-provide-renewable-natural-gas-23525746/ http://herald-review.com/business/energy/adm-ameren-partnering-to-provide-renewable-natural-gas/article_8f13c92f-d224-5279-a2a2-99b4de1a2f0f.html
A15: BioEnergy Devco Jessup | B15: OPERATIONAL | C15: BioEnergy Devco | D15: Howard | E15: MD | F15: Q3 2022 | G15: BioEnergy Devco | H15: 110,000 ton per year facility located at the Maryland Food Center, a wholesale hub in Jessup, MD. System to go into commissioning Q4 2021, RNG production expected Q2 2022. | I15: BTS Biogas CSTR and membrane separation upgrading | J15: 110,000 tons per year | K15: 300 (based on 110,000 TPY) | L15: Food waste from wholesale market | M15: Maryland Food Center Authority | N15: =O15/0.6 -> 1582952.8 | O15: =P15/(0.001*365*0.9) -> 949771.69 | P15: 312000 | Q15: PIPELINE (For vehicle/other) | R15: Unknown | S15: =P15/0.112194 -> 2780897.4 | X15: Pending | Y15: https://www.wastedive.com/news/bioenergy-devco-newlight-partners-anaerobic-digesters/560495/ https://www.bioenergy-news.com/news/bts-biogas-bioenergy-devco-join-forces-on-us-ad-projects/ https://bioenergydevco.com/gov-hogan-joins-state-officials-at-ribbon-cutting-for-bioenergy-devcos-anaerobic-digester/ https://bioenergydevco.com/maryland-bioenergy-center/
A16: NW Natural/Tyson Foods RNG, Lexington NE | B16: OPERATIONAL | C16: NW Natural | D16: Dawson | E16: NE | F16: Construction began Q1 2021 | G16: NW Natural , BioCarbN, Cross River Infrastructure Partners | H16: The first of four potential projects under the NW Natural/Tyson joint venture will be in Lexington, Neb., next to a Tyson Fresh Meats beef packaging plant and will use anaerobic digester technology to convert the plant's animal waste and other byproducts into RNG, which will be processed to pipeline quality specifications. The RNG will be injected into Black Hills Energy's local distribution system, and the associated renewable thermal certificates will be used to meet targets under Oregon Senate Bill 98, enacted in 2019, which supports renewable energy procurement and investment by natural gas utilities. | L16: Animal waste, wastewater, food processing by products | M16: Tyson plant | N16: =O16/0.6 -> 963977.68 | O16: =P16/(0.001*365*0.9) -> 578386.61 | P16: 190000 | Q16: PIPELINE (For vehicle/other) | S16: =P16/0.112194 -> 1693495.2 | Y16: https://www.newsdata.com/clearing_up/courts_and_commissions/nw-natural-proposes-rng-project-in-nebraska-for-tyson-foods/article_d2afec2e-520a-11eb-9ac3-5f99aa0fc0d8.html https://www.naturalgasintel.com/nw-natural-taking-partners-for-more-u-s-rng-production/ https://www.biocarbn.com/wp-content/uploads/2021/01/NW-Natural-and-BioCarbN-Form-Innovative-Renewable-Natural-Gas-Partnership-with-Tyson-Foods-2021.pdf
A17: Central Ohio BioEnergy (Equilibrium Capital) | B17: OPERATIONAL | C17: Equilibrium Capital | D17: Franklin | E17: OH | F17: 2010 | G17: quasar energy group; Solid Waste Authority of Central Ohio (SWACO); Kurtz Bros., Inc. | H17: Processes biosolids from the City of Columbus to generate electricity and CNG for an on-site fueling station; also uses regional food waste and FOG (fats, oil and grease). According to presentation, 3600 GGE/day | I17: Complete Mix? | J17: 90,000 tons/yr. | L17: Food waste, FOG and manure from farms | M17: City of Columbus | N17: =O17/0.6 -> 747960 | O17: =P17/(0.001*365*0.9) -> 448776 | P17: =S17*0.112194 -> 147422.92 | Q17: BOTH | R17: Public | S17: =3600*365 -> 1314000 | U17: 8,760 MWh/yr. | X17: Yes | Y17: https://www.bioohio.com/item/quasar-energy-group-llc-central-ohio-bioenergy/ https://www.americanbiogascouncil.org/projectProfiles/columbus_oh.pdf https://energy-vision.org/case-studies/columbus-bioenergy/ https://ideas.uncc.edu/sites/ideas.uncc.edu/files/media/mel-kurtz-bioenergy-symposium-for-distribution-0.pdf
A18: Zanesville Energy (Quasar) | B18: OPERATIONAL | C18: Quasar | D18: Muskingum | E18: OH | F18: 2010 | G18: quasar energy group, Ohio State University | H18: Generates on-site electricity, heat and RNG through both liquid and solid state anaerobic digestion; on-site CNG fueling station. Feedstock includes food waste, FOG and biosolids. Centralized/regional facility | I18: Complete Mix | J18: 35000 tons/year | L18: Food waste, FOG, biosolids | N18: =O18/0.6 -> 336581.67 | O18: 201949 | P18: 66340 | Q18: BOTH | R18: Private | S18: 657000 | U18: 8760 MWh year | V18: 4623 (methane) | X18: Yes | Y18: https://www.bioohio.com/item/quasar-energy-group-llc-zanesville-energy/ http://www.greenenergyohio.org/page.cfm?pageID=2949 http://quasareg.com/New/locations/
A19: Seaboard Foods/High Plains Bioenergy | B19: OPERATIONAL | C19: High Plains Bioenergy | D19: Texas | E19: OK | F19: 42948 | G19: High Plains Bioenergy | H19: High Plains Bioenergy produces biogas from the Seaboard Foods' waste water system, which is then scrubbed to pipeline quality using a pressure swing adsorption system and delivered to the interstate pipeline network to be used by the public as a renewable energy source. According to company website, there is a CNG filling station located across the road from the plant, which provides fuel to some of the company's 180 CNG vehicles, is also open to public. | I19: Lagoons | L19: Waste water from pork processing plant | M19: Seaboard Foods | N19: =O19/0.6 -> 1111111.1 | O19: =P19/(0.001*365*0.9) -> 666666.67 | P19: =600*365 -> 219000 | Q19: BOTH | R19: Public | S19: =P19/0.112194 -> 1951976 | U19: None | X19: Yes | Y19: https://highplainsbioenergy.com/Biogas.aspx https://www.bloomberg.com/profiles/companies/0537045D:US-high-plains-bioenergy-llc https://seaboardfoods.com/About/Pages/Facts_Figures_Bioenergy.aspx https://www.wattagnet.com/articles/32044-high-plains-bioenergy-starts-operations-of-expanded-biogas-recovery-plant
A20: Wasatch Resource Recovery | B20: OPERATIONAL | C20: Through PPP co-owned by ALPRO Energy and Water and South Davis Sewer District | D20: Davis | E20: UT | F20: 2018 | G20: Wasatch Resource Recovery | H20: WRR is a public-private partnership between ALPRO Energy & Water (ALPRO) and the South Davis Sewer District (SDSD). The facility will be using state-of-the-art equipment, much of which is supplied by GE-Monsal, a strategic partner in the project. The WRR is sited right next to the existing South Plant wastewater treatment facility and will use much of the existing plants’ facilities to support the project. In the first phase of construction, two 2.5-million gallon tanks will be built to be used at the WRR facility for digestion. In this public-private partnership, the SDSD will operate the WRR facility and ALPRO will manage the feed stock and the energy and fertilizer offtakes. Original project plan involved 4 digesters, a row of greenhouses, a boiler building, a chemical & dewatering building, and a depackaging facility.Two of four planned digesters are in place, units three and four are several years down the road as of 2021. Planned greenhouses for site have been deferred. | I20: Wet, complete mix | J20: 500-700 tpd | K20: 1400 tpd | L20: Prepared and packaged foods, fruits and vegetables, meat and dairy, fats, oils, grease, expired beverages, screened curbside wastes and liquid organics from major food processors | M20: Local supermarkets, restaurants, food processors. Bulk of waste will be from manufacturing. Delivered by local haulers. 2021, started accepting limited amounts of residential waste via dropoff, will be doing a pilot for curbside pick up with local hauler. | N20: =O20/0.6 -> 5000000 | O20: 3000000 | P20: =O20*(0.001*365*0.9) -> 985500 | Q20: PIPELINE (For vehicle/other) | R20: No | S20: =P20/0.112194 -> 8783892.2 | X20: Unknown | Y20: https://www.wastetodaymagazine.com/article/utah-wasatch-resource-recovery-chooses-ge/ https://www.boisestatepublicradio.org/post/digesting-thanksgiving-leftovers-one-utah-facility-turning-food-waste-energy#stream/0 https://www.waste360.com/business/wasatch-resource-recovery-s-olsen-bowerman-finds-hope-waste http://wasatchresourcerecovery.com/ https://www.ksl.com/article/46680173/how-this-north-salt-lake-plant-will-turn-table-scraps-into-natural-gas-for-europe https://www.facebook.com/WasatchResourceRecovery/
A21: Impact Bioenergy Vashon Island | B21: OPERATIONAL | C21: Impact Bioenergy | D21: King | E21: WA | F21: 43556 | G21: Impact Bioenergy | H21: Project processes waste from a tofu factory. Small scale project, as of July 2020 providing fuel for single vehicle. | I21: CSTR? | J21: 8000 lbs/day | K21: 4 | L21: Okara and whey | M21: Island Spring Organics | N21: 21500 | O21: =N21*0.6 -> 12900 | P21: =O21*(0.001*365*0.9) -> 4237.65 | Q21: BOTH | R21: Private | S21: =P21/0.112194 -> 37770.736 | T21: =365*125 -> 45625 | Y21: https://www.vashonbeachcomber.com/news/island-anaerobic-digester-unveiled/ https://www.vashonbeachcomber.com/news/island-based-impact-bioenergy-fuels-up-car-with-food-waste/ https://impactbioenergy.com/wp-content/uploads/2019/06/Vashon-Bioenergy-Farm-Island-Spring-Organics-NAUTILUS-overview.pdf
A22: UNDER CONSTRUCTION AS OF 12/31/2023
A23: [Divert Project] | B23: UNDER CONSTRUCTION | C23: Divert, Inc. | D23: Stanislaus | E23: CA | F23: early 2024 | G23: Divert, Inc. | H23: October 2022 announcement of offtake agreement with bp. April 2023 announcment of greoundbreaking of Turlock facility, with estimated completion early 2024. Reached interconnection agreement with PG&E for RNG to enter PG&E’s on-site transmission line, replacing fossil gas with a carbon negative renewable fuel to supply homes and businesses. | J23: 100,000 tons per year | K23: 274 tons of wasted food per day (based on 100,000 TPY) | V23: 23,000 metric tons of carbon dioxide a year | Y23: https://www.bloomberg.com/press-releases/2022-10-06/divert-inc-announces-renewable-natural-gas-offtake-agreement-with-bp https://www.wastedive.com/news/divert-bp-offtake-agreement-rng-food-digestion/633564/ https://finance.yahoo.com/news/divert-inc-breaks-ground-wasted-165900807.html?guce_referrer=aHR0cHM6Ly93d3cucm5nY29hbGl0aW9uLmNvbS8&guce_referrer_sig=AQAAAD7TMJ2aWb0ydq0QlOzb71OH3fSuGWU-xuuIvhXOTEf5RbXM0fC3uTesPB9jGuETf1HRy97-mp-5glst0OjEO7ZRDG9GK6v9MaiGVTpANY5vgHQJbz9lcjl2k58w8H2k0kpYR04T9Y_ymvWjsNxDJ9URuBpcvMuYxkA9McwbAn89&guccounter=2 https://www.turlockjournal.com/news/local/new-turlock-facility-looks-to-tackle-nations-food-waste-problem/
A24: Green Era Urban Farming Campus, Chicago | B24: UNDER CONSTRUCTION | C24: Green Era Sustainability? | D24: Cook | E24: IL | F24: Construction to Start Q3 2020 | G24: Green Era; Greater Auburn-Gresham Development Corp; BP? | H24: "Green Era is developing a renewable energy facility in South Chicago. The project will be located on a vacant brownfield site in an area with urgent need for cleanup and economic development. Using anaerobic digestion, Green Era will divert inedible food waste from landfills to produce clean, renewable energy and nutrient-rich soil, which will be used as a critically needed input in the expansion of fresh local food production. The end result will have positive social and environmental impacts, while also creating jobs, sustainable neighborhoods and healthier lifestyles." Project will produce compost for an urban farming component that will grow ~26,000 lbs of food annually; area is considered food desert. | J24: 85,000 tons per year | K24: 230 (based on 85,000 TPY) | L24: "Recycled food and waste" | P24: 112194 | Q24: UNKNOWN | T24: 1000000 | V24: 42500 | Y24: https://www.bioenergy-news.com/news/green-era-bp-partner-to-sell-rng-produced-via-chicago-ad-project/ https://www.waste360.com/food-waste/chicago-green-campus-plans-turn-food-waste-energy-and-grow-more-food https://www.greenerachicago.com/ https://www.wastedive.com/news/chicago-green-era-urban-farm-anaerobic-digester/583764/ http://www.gagdc.org/news/3740 https://www.renewableenergymagazine.com/biogas/urban-farming-campus-on-chicago-s-south-20200824
A25: Linden Renewable Energy (LRE) Project | B25: UNDER CONSTRUCTION | C25: RNG Energy Solutions | D25: Union | E25: NJ | F25: Construction began December 2023; target completion date in Q1 2026 | G25: RNG Energy Solutions in partnership with SJI and Captona | H25: The LRE Project will accept a wide range of feedstock, including food waste from industrial, commercial, and institutional entities, as well as grease waste from restaurants and other food service establishments. It will convert up to 1,475 tons of waste to produce up to 3,783 MMBtu/day of RNG— the energy equivalent value of 30,200 gallons of gasoline per day. The LRE Project includes development and construction of multiple off-site food waste pre-processing and depackaging operations in New York City, New York State and New Jersey. Work was slated to begin in December 2023, with a target completion date in Q1 2026. The LRE Project earlier received approval from the NJ Economic Development Authority for $214 million in Industrial Development Revenue Bonds. | K25: 1475 | L25: food waste (SSO) and fats, oils, grease (FOG) | M25: industrial, commercial, and institutional entities, as well as restaurants and other food service establishments | P25: 1380795 | Q25: PIPELINE (For vehicle/other) | S25: 11023000 | Y25: https://www.rngenergysolutions.com https://njbiz.com/major-food-waste-to-renewable-natural-gas-facility-set-for-linden/ https://www.globenewswire.com/news-release/2023/12/20/2799284/0/en/SJI-and-Captona-Announce-Construction-of-one-of-the-Largest-Food-Waste-to-RNG-Facilities-in-the-US.html https://ucnj.org/wp-content/uploads/2020/07/UCUA-Linden-Renewable-Energy-LLC-Plan-Amendment.pdf https://www.mycentraljersey.com/story/news/local/union-county/2022/02/15/renewable-energy-plant-linden-ready-construction/6784189001/
A26: American Organic Energy | B26: UNDER CONSTRUCTION | C26: American Organic Energy | D26: Suffolk | E26: NY | F26: Groundbreaking April 2022. | H26: American Organic Energy is a project by the owners of Long Island Compost. Food waste from Long Island will be collected, separated, pre-processed, broken down and ultimately transformed into electrical energy, renewable natural gas, fertilizer and nutrient-rich water. | I26: CSTR | J26: 180,000 tons per year | K26: ~500 | L26: Food waste, green waste, FOG | N26: =O26/0.6 -> 942916.4 | O26: =P26/(0.001*365*0.9) -> 565749.84 | P26: =S26*0.112194 -> 185848.82 | Q26: PIPELINE (For vehicle/other) | R26: Unknown | S26: =1900000/1.147 -> 1656495.2 | U26: 2MW | Y26: https://www.wastetodaymagazine.com/article/american-organic-energy-anaerobic-digester-yaphank-new-york/ https://libn.com/2022/04/11/anaerobic-digester-facility-coming-to-yaphank/ https://www.newsday.com/long-island/politics/compost-energy-lipa-renewable-natural-gas-xxkbg6ea
A27: Synthica St. Bernard | B27: UNDER CONSTRUCTION | C27: Hamilton RNG, a JV of UGI Energy Services and Synthica Energy. | D27: Hamilton | E27: OH | F27: Groundbreaking July 2023, commercial operation Q4 2024 | G27: Hamilton RNG | H27: The digester is expected to be completed in late calendar 2024 and will process approximately 190,000 annual tons of food waste from nearby food manufacturers in an anaerobic digester. The project is expected to generate approximately 250,000 MMBTUs (million BTUs) of pipeline-quality RNG each year that will be injected into a local natural gas pipeline on the regional distribution system. Digester will be complete mix, upgrading will be water wash, no vendors selected yet. Gas most likely destined for transportation markets | I27: CSTR | J27: ~190,000 tons annually | K27: ~500 TPD | L27: Food from nearby manufacturers | M27: Nearby manufacturers | N27: =O27/0.6 -> 1268391.7 | O27: =P27/(0.001*365*0.9) -> 761035.01 | P27: 250000 | Q27: PIPELINE (For vehicle/other) | S27: =P27/0.112194 -> 2228283.2 | X27: Pendiong | Y27: https://www.businesswire.com/news/home/20210804006006/en/UGI-and-Synthica-Energy-Partner-to-Develop-Renewable-Natural-Gas https://synthica.com/synthica-energy-st-bernard/ https://biomassmagazine.com/articles/20260/ugi-energy-services-synthica-energy-break-ground-on-rng-project
A28: Port of Morrow, Boardman, Oregon | B28: UNDER CONSTRUCTION | C28: Port of Morrow | D28: Morrow | E28: OR | F28: Digster construction starting Fall 2021; full project operational 2024. | G28: Port of Morrow; partners being identified. | H28: As of September 2021, Port is going ahead with 3 anaerobic digester project, will add gas upgrading later. Hoping to have all in place by 2024. Digester would use process water from food processing businesses at port to produce renewable natural gas, organic fertilizer and clean water; primary feedstocks being proposed consist of produce waste including onion and potato waste solids, cheese, FOG. Anticipate producing ~1750 MMBTU/day. November 2022, they are begining construction on three lagoon digesters, which are feasible in their climate because they will be getting warm process water from the food manufacturers. Once one of them is complete, they will test gas volume and quantity, then work on identifying upgrading parter. Still foresee all operational by late 2024. | I28: Covered lagoons | J28: ?? | K28: ?? | L28: Leftover potato peelings and onion skins, cheese, FOG from local food processors. | M28: Local food processors, local dairy farm | N28: =O28/0.6 -> 3240740.7 | O28: =P28/(0.001*365*0.9) -> 1944444.4 | P28: =1750*365 -> 638750 | Q28: PIPELINE (For vehicle/other) | S28: =P28/0.112194 -> 5693263.5 | T28: 7665000 | U28: N/A | V28: 8400 | X28: Pendiong | Y28: http://biomassmagazine.com/articles/11178/novus-pacific-to-build-full-scale-oregon-renewable-energy-plant http://www.novus-energy.com/project-highlights/novus-pacific-llc-at-port-of-morrow/ https://www.rd.usda.gov/files/Novus_Pacific_EA_Supplemental.pdf
A29: Rhode Island Bioenergy Facility (formerly Orbit Energy) | B29: UNDER CONSTRUCTION | C29: Anaergia, which bought former bought former Orbit Energy AD electricity facility summer 2021 | D29: Providence | E29: RI | F29: Construction underway in 2023, expected completion later in 2023 | G29: Anaergia | H29: Anaergia recently acquired the facility, which is currently producing renewable electricity, and is upgrading the plant using its BUG biogas upgrading system to produce RNG. The facility will divert over 100,000 tons per year of food waste from landfills and convert the waste to renewable fuel. RIBF is expected to produce over 300,000 MMBtu of carbon-negative RNG starting later in 2023, which will make it New England’s largest anaerobic digestion-to-RNG facility. In addition, the plant will recycle the nutrient-rich solid residual left over after anaerobic digestion to enrich New England soils and reduce the use of fossil fuel-derived fertilizers. | I29: CSTR | J29: 100,000 TPY | K29: ~270 | L29: Food waste from area supermarkets, schools and food manufacturers | M29: Area businesses and institutions | N29: =O29/0.6 -> 1623541.3 | O29: =P29/(0.001*365*0.9) -> 974124.81 | P29: 320000 | Q29: PIPELINE (For vehicle/other) | V29: 41,000 metric tons of CO2e | Y29: https://www.wastetodaymagazine.com/article/anaergia-acquires-rhode-island-bioenergy-facility/ http://www.dem.ri.gov/programs/wastemanagement/facilities/OrbitEnergymonitoringplans.pdf https://www.wastedive.com/news/rhode-island-first-anaerobic-digester/539063/ https://www.businesswire.com/news/home/20230118005363/en/Canadian-Owned-Irving-Oil-Selects-Anaergia-Inc.-as-a-Supplier-of-Carbon-Negative-Renewable-Natural-Gas-for-its-Operations-Including-the-Saint-John-Refinery#:~:text=The%20RNG%2C%20which%20is%20made,are%20transformed%20into%20renewable%20fuel. https://www.wastedive.com/news/anaergia-earnings-rialto-bioenergy-los-angeles-organics/647305/ https://www.anaergia.com/the-40-million-ton-gold-mine/
A30: McCall Farms | B30: UNDER CONSTRUCTION | C30: McCall Farms | D30: Florence | E30: SC | F30: First RNG produced 2022 but expansion underway to double capacity | G30: GreenGasUSA and Guild Associates | H30: Cannery waste to pipeline RNGz. GreenGasUSA will be doubling the digester gas production capacity, as two lagoons will soon be operational at the site. Guild Associates will provide a second Molecular Gate™ CO2 removal Pressure Swing Adsorption (PSA) system for this expansion in addition to the equipment under construction currently. This project, with Duke University as an RNG consumer (95,000 MMBTUs), will convert biogas methane from agricultural waste into Renewable Natural Gas for injection into the natural gas pipeline. A Mercedes-Benz plant in SC has also signed a contract to buy RNG from the plant. RNG Coalition notes that ened uses will be transportation, thermal. | I30: Covered lagoons | Q30: PIPELINE (For vehicle/other) | V30: 184000 metric tons of CO2e | Y30: https://www.guildassociates.com/guild-associates-and-greengasusa-to-expand-mccall-farms-project/ https://www.today.duke.edu/2021/07/novel-renewable-natural-gas-partnership-will-move-duke-toward-carbon-neutrality https://greengasusa.com/greengasusa-announces-rng-project-from-food-and-agricultural-waste-in-sc/?ss_source=sscampaigns&ss_campaign_id=600de1a315b73f591e6ce748&ss_email_id=600e053508f3860a07fd67b4&ss_campaign_name=GreenGasUSA%20Announces%20RNG%20Project%20from%20Food%20and%20Agricultural%20Waste%20in%20SC&ss_campaign_sent_date=2021-01-24T23%3A39%3A51Z https://charlestonbusiness.com/news/manufacturing/82062/ https://www.wbtw.com/news/pee-dee/florence-county/south-carolina-companies-team-up-for-renewable-energy-project-at-mccall-farms/ https://agriculture.sc.gov/greengasusa-mercedes-benz-mccall-farms-expand-carbon-friendly-commitment-in-sc/
A31: 3 Rivers Jack Daniel's | B31: UNDER CONSTRUCTION | C31: 3 Rivers Energy Partners | D31: Moore | E31: TN | F31: Construction underway as of June 2023, with May 2024 estimated completion | G31: 3 Rivers Energy, BIOFerm | H31: The facility will utilize spent distiller’s grains from the Jack Daniel Distillery to produce renewable natural gas (RNG) and a low-carbon natural fertilizer able to support tens of thousands of acres of farmland. Will supply pipeline; end-use unclear as of Sep 2023. The new process is also expected to reduce the distillery’s energy use by around 30%. | L31: Distillery mash from Jack Daniel's whiskey production. | N31: =O31/0.6 -> 5580923.4 | O31: =P31/(0.001*365*0.9) -> 3348554 | P31: 1100000 | Q31: PIPELINE (For vehicle/other) | Y31: https://www.globenewswire.com/news-release/2022/11/01/2545827/0/en/3-Rivers-Energy-Partners-Announces-Project-With-Jack-Daniel-s-to-Convert-Spent-Distillers-Grains-Into-Renewable-Natural-Gas-and-Natural-Commercial-Fertilizer.html https://www.tullahomanews.com/news/local/3-rivers-energy-partners-with-jack-for-renewable-energy/article_1ecb9102-b466-11ed-a565-b3bac3bb84e3.html https://www.biofermenergy.com/bioferm-selected-by-3-rivers-energy-partners-for-revolutionary-renewable-energy-project-near-the-jack-daniel-distillery/ https://captimes.com/news/business/jack-daniels-whiskey-waste-becomes-natural-gas-thanks-to-madison-firm/article_14e98d46-94cd-5b3b-9c39-9627cce37670.html
A32: Divert Longview | B32: UNDER CONSTRUCTION | C32: Divert, Inc. | D32: Cowlitz | E32: WA | F32: 45176 | G32: Divert, Inc. | H32: $100 million facility to bring in food waste from 650 WA and OR grocery stores. October 2022 announcement of offtake agreement with bp. Groundbreaking ceremony September 2023, estimated completion in 2024. RNG from food waste will be injected into a nearby Cascade Natural Gas pipeline. | J32: 100,000 tons per year | V32: 23,000 metric tons of greenhouse gas emissions annually | Y32: https://tdn.com/news/local/business/renewable-biogas-plant-planned-for-longview-could-be-first-of-its-kind-in-washington-state/article_95db7b23-cbe4-5a7e-8386-e99ecd0bb8e3.html http://www.divertinc.com/ https://www.bloomberg.com/press-releases/2022-10-06/divert-inc-announces-renewable-natural-gas-offtake-agreement-with-bp https://www.wastedive.com/news/divert-bp-offtake-agreement-rng-food-digestion/633564/ https://globalnews.ca/news/9945552/enbridge-divert-break-ground-renewable-fuel-facility-washington/ https://www.eastoregonian.com/news/agriculture/washington-plant-will-convert-food-waste-into-renewable-natural-gas/article_15c75f6a-5fd6-556f-aea1-bf1b678a1e62.html https://tdn.com/news/local/business/divert-biogas-biofuel-jobs-longview-mint-farm/article_96aa406c-3b78-11ee-bc09-efefe20fde3d.html
A33: CONFIRMED CANCELLED/SHUTDOWN AS OF 12/31/2023
A34: Colony Energy Partners Tulare LLC | B34: CANCELLED | D34: Tulare | E34: CA | G34: Colony Energy Partners, LLC | H34: Divert waste from California’s landfills in order to produce renewable biomethane, which will be fed directly into the natural gas grid via a SoCalGas transmission line adjacent to the property. The biomethane will also be supplied as a diesel alternative to San Joaquin Valley’s on-road truck market through a public access Bio-CNG fueling station located on the property. The facility will integrate combined heat and power (CHP) cogeneration modules, a portion of which can run on the biogas to generate electric and thermal energy for the facility. Any excess thermal energy will be exported to heat the adjacent City of Tulare Industrial Wastewater Treatment Plant’s digester. California Energy Commission awarded $5 million grant for this $25 million project | J34: 500 tons/day | L34: Dairy manure, food and agricultural processing residuals, restaurant and cafeteria food scraps, restaurant grease trap residuals, and organic municipal solid waste | N34: =O34/0.6 -> 2222222.2 | O34: =P34/(0.001*365*0.9) -> 1333333.3 | P34: 438000 | Q34: BOTH | S34: =P34/0.112194 -> 3903952.1 | U34: 1,200 kW | V34: 41,850 tons/yr. | Y34: http://www.colonyenergypartners.com/tulare-bio-gas/ http://biomassmagazine.com/articles/11418/california-energy-commission-awards-biogas-project-5-million http://www.sandiegouniontribune.com/news/sd-tm-0729-digester-20170719-story.html
A35: Mendota Advanced Bioenergy Beet Cooperative | B35: SHUT DOWN | D35: Fresno | E35: CA | G35: Mendota Advanced Bioenergy Beet Cooperative; Mendota Bioenergy, LLC; California Energy Commission | H35: A large system to produce electricity, CNG for pipeline/vehicle fuel, and ethanol production from beets. The demonstration plant came on line in December 2014 and will operate through the summer of 2015 when efforts will shift to the development, construction, and operation of Advanced Bioenergy Center—Mendota (ABC-M), the first of several California-based full-scale commercial 15-MGY integrated biorefineries. ABC-M is targeted for a late 2017 or early 2018 startup. | J35: 4,000 tons/day | L35: Beets | N35: =O35/0.6 -> 7333.3333 | O35: 4400 | P35: =O35*(0.001*365*0.9) -> 1445.4 | Q35: BOTH | S35: =P35/0.112194 -> 12883.042 | U35: 6.3 MW | Y35: https://www.arb.ca.gov/fuels/lcfs/workgroups/lcfssustain/tisher.pdf
A36: Sacramento Biodigester/Incline Clean Energy (formerly Clean World) | B36: SHUT DOWN; FUTURE POTENTIAL? | C36: Fueling station, Atlas ReFuel; digester and upgrading facility, Incline Clean Energy | D36: Sacramento | E36: CA | F36: December 2012 | G36: BioCNG; CleanWorld; Atlas Disposal | H36: Converts food waste from area food processing companies, restaurants and supermarkets into RNG, electricity and soil-amendment products; RNG fuels waste disposal vehicles, school buses and fleet vehicles throughout the Sacramento region via an on-site fueling station. Currently 100% of gas goes to vehicle fueling, in the future 85% will go to vehicle fueling and 15% to on-site electricity use. | I36: Thermophilic, three stage, complete mix | J36: 2016, 24,000 tons/yr.; Jan. 2017, running at between 60% and 100% capacity (100 tpd) | K36: 100 | L36: Food waste | M36: Atlas Disposal | N36: =O36/0.6 -> 145493.59 | O36: =P36/(0.001*365*0.9) -> 87296.153 | P36: =S36*0.112194 -> 28676.786 | Q36: VEHICLE FUEL | R36: Yes | S36: 255600 | T36: 657000 | U36: 3,170 kWh/yr., goes toward powering station, digester, upgrading | V36: 18,250 tons/yr. | X36: Yes | Y36: http://www.cleanworld.com/news/cleanworlds-sacramento-biodigester-named-international-bioenergy-project-of-the-year/ http://biocng.us/wp-content/uploads/2015/06/CleanWorld-Fact-Sheet-2015.pdf https://refuelenergypartners.com/
A37: Santa Rosa, CA FARMS to FUEL Project | B37: CANCELLED | D37: Sonoma | E37: CA | G37: BioStar Systems, LLC; Sonoma County Water Agency; Sonoma Country Transit | H37: Create pipeline quality gas for vehicle fuel; used to fuel Sonoma County Transit fleet, with excess sent to nearby fueling stations | I37: Thermophilic (50-55C) | J37: 75,000 gal/day dairy waste; 66,000 gal/day food waste | L37: Dairy and food waste | O37: 240,000 (148,000 SCFD used by Sonoma County Transit fleet) | P37: =2400008*(0.001*365*0.9) -> 788402.63 | Q37: PIPELINE | S37: =P37/0.112194 -> 7027137.2 | U37: 5.2 MWh | V37: 41,300 tons/year | X37: Unknown | Y37: http://www.northbaybusinessjournal.com/csp/mediapool/sites/NBBJ/IndustryNews/story.csp?cid=4179855&sid=778&fid=181 http://www.sonoma-county.org/prmd/b-c/pcbza/act_20110526.pdf
A38: UC Davis Renewable Energy Anaerobic Digester (READ) | B38: PROJECT SUSPENDED | C38: UC Davis | D38: Yolo | E38: CA | F38: 2014 | G38: UC Davis; CleanWorld | H38: 3 anaerobic reactor tanks. Thermophilic. Total volume of 450,000 gallons. 4 microturbines. Currently produces heat and electricity; additional capability may be added to purify and compress the biogas for producing compressed or liquefied fuels; also produces ethanol from food waste such as sugar beets | I38: Thermophilic, three stage, complete mix | J38: 20000 tons/yr. | K38: 50 | L38: Food waste from dining halls, commercial restaurants, retail produce waste. food scraps from commercial food supply companies, mouse bedding from lab, horse manure | M38: UC Davis dining halls, local food processors | N38: 222000 | O38: =N38*0.6 -> 133200 | P38: =O38*(0.001*365*0.9) -> 43756.2 | Q38: OTHER | S38: =P38/0.112194 -> 390004.81 | T38: N/A | U38: 925 kW | V38: 13,500 tons | X38: N/A | Y38: http://www.energy.ca.gov/2017publications/CEC-500-2017-021/CEC-500-2017-021.pdf https://www.ucdavis.edu/news/biodigester-turns-campus-waste-campus-energy https://americanbiogascouncil.org/projectProfiles/ucdavis_to_print.pdf
A39: Heartland Biogas | B39: SHUT DOWN | D39: Weld | E39: CO | G39: Heartland Renewable Energy LLC, EDF Renewable Energy | H39: 6 Bio Reactors (Tanks and Lagoons) produce the biogas which is then passed through a Sulfur Scrubber and a DeOxo unit so that it can be injected into a pipeline and sent to the Sacramento Municipal Utility District (SMUD) | L39: Organic Feedstock and dairy cow manure | M39: A1 organics | N39: =O39/0.6 -> 8000 | O39: 4800 | P39: =O39*0.001*365*0.9 -> 1576.8 | Q39: PIPELINE | S39: =P39/0.112194 -> 14054.227 | Y39: http://www.greeleytribune.com/news/local/heartland-biogas-says-shut-down-ongoing-amid-court-battle-with-weld-county/ http://www.boulderweekly.com/boulderganic/requiem-for-a-digester/ https://www.facebook.com/greeleytribune/posts/10155535036633077 http://www.rewmag.com/article/heartland-biogas-edf-renewable-partnership/ http://bizwest.com/a1-organics-heartland-biogas-complete-3-5m-facility-expansion/ http://www.npr.org/sections/thesalt/2016/04/05/472673127/how-colorado-is-turning-food-waste-into-electricity
A40: BioEnergyDevCo Principio Business Park | B40: CANCELLED; FUTURE POTENTIAL? | C40: BioEnergy Dev Co | D40: Cecil | E40: MD | G40: BioenergyDevCo? | H40: Taking ag waste from area poultry processors and food waste from area producers. Project is going in at business park, initial plan is to provide RNG for campus fleet, looking at pipeline injection later | J40: 70-100,000 tons mixed food and ag waste annually | L40: Mixed food and ag (poultry farmers) | Q40: BOTH | Y40: https://www.waste360.com/anaerobic-digestion/bioenergy-devco-advances-expansion-plans https://www.prnewswire.com/news-releases/bioenergy-devco-to-purchase-perdue-agrirecycle-organic-soil-composting-facility-in-delaware-300962924.html
A41: Michigan State University South Campus Anaerobic Digester | B41: SHUT DOWN; FUTURE POTENTIAL? | C41: MSU | D41: Ingham | E41: MI | G41: Michigan State University | H41: Biogas is used to power a 400 kW combined heat and power unit. Upgrading biogas to CNG for the campus vehicle fleet is a future consideration. Gases cleaned using a series of filters (water vapor via chiller, H2S via iron sponge, siloxanes and volatile organic carbons via carbon filter) prior to going to microturbines. CHP | I41: Single tank complete mix, 25 day retention time | J41: 66 tpd | L41: Manure, Food processing waste, FOG, Cafeteria food waste | M41: Michigan State University and local food processors/service | N41: 177000 | O41: =N41*0.6 -> 106200 | P41: =O41*0.001*365*0.9 -> 34886.7 | Q41: VEHICLE FUEL | U41: 2600 MWh/yr. via 380 kW CHP unit | Y41: https://www.egr.msu.edu/bae/adrec/feature/south-campus-anaerobic-digester http://ipf.msu.edu/green/practices/anaerobic-digester.html
...

Sheet Landfills
A1: KEY: | B1: Project added 2023 | G1: Color coding generally applies to numeric values only.
B2: Information provided or confirmed by contact | G2: Individual values are often drawn from different sources, and so may appear inconsistent-- e.g., gas going for upgrading may be more than total amount of gas collected
B3: Value calculated based on other info provided
B4: Value from LMOP
B5: Value from website/press
A6: GENERAL INFORMATION | H6: PROJECT INFORMATION | K6: INPUTS | N6: OUTPUTS | U6: ADDITIONAL INFORMATION
A7: Landfill/Project Name | B7: Projected status 12/31/2023 | C7: Owner | D7: Waste In Place (tons) | E7: Daily intake, tons | F7: County | G7: State | H7: Upgrading Start Date | I7: Developer(s) | J7: Description | K7: LFG Flow to Upgrading Project (mmscfd) | L7: Total LFG Collected (mmscfd) | M7: LFG Flared (mmscfd) | N7: Upgraded gas, SCFD | O7: Upgraded MMBTU/yr | P7: RNG Disposition | Q7: If producing vehicle fuel, public filling station? | R7: GGE/yr | S7: Capacity (GGE/yr) | T7: Electricity | U7: Annual metric tonnes CO2e eliminated | W7: RIN Registrant? | X7: References
A8: OPERATIONAL AS OF 12/31/2023
A9: City of Fort Smith Landfill (Morrow Renewables) | B9: OPERATIONAL | C9: Fort Smith Department of Sanitation | D9: 10034620 | F9: Sebastian | G9: AR | H9: 38848 | I9: Morrow Renewables, LLC, Cambrian Energy Development, LLC | J9: Physical solvent process with patented enhancements and catalytic oxygen removal - removes CO2, H2O, H2S, siloxanes, and other impurities from LFG. Creates high BTU RNG injected into the pipeline infrastructure. Gas used down the pipeline for vehicle fuel. | K9: 2.7 | L9: 4.387 | M9: 0.297 | N9: =O9/(0.9*0.001*365) -> 1627397.3 | O9: 534600 | P9: PIPELINE (For vehicle/other) | Q9: No | R9: =O9/0.112194 -> 4764960.7 | T9: N/A | U9: .35 MMT | W9: Yes | X9: https://morrowrenewables.com/portfolio/ https://talkbusiness.net/2021/04/fort-smith-board-approves-cng-fueling-station-plans-for-conversion-of-sanitation-trucks/
A10: Eco Vista | B10: OPERATIONAL | C10: Waste Management Renewable Energy | D10: 9509704 | F10: Conway | G10: AR | H10: 45108 | J10: The Eco Vista facility spans 14,430 square feet. It is expected to recover and distribute approximately 750,000 metric million British thermal units (mmBtu) per year of RNG, which could serve the equivalent of 25,000 households annually or 650 heavy-duty vehicles. WM will allocate a portion of the RNG for its U.S. fleet of compressed natural gas (CNG) vehicles. The RNG facility at Eco Vista processes the increasing volumes of biogas collected from the landfill — generated during the decomposition of organic material — into pipeline-quality gas to be delivered to Energy Transfer’s Enable Gas Transmission pipeline system. According to communication with WMI, project will push 2500 SCFM of raw gas for upgrading. Upgrading technology Adsorption Research Inc. PSA system. | K10: =(2500*60*24)/1000000 -> 3.6 | L10: 2.457 | M10: 0 | N10: =(K10*1000000*0.55) -> 1980000 | O10: 750,000 | P10: PIPELINE (For vehicle/other) | Q10: NO | R10: =750000/0.112194 -> 6684849.5 | T10: 3.8 MW | U10: 40,000 tons per year | W10: Yes | X10: https://www.wmsolutions.com/locations/details/id/168 https://www.adeq.state.ar.us/sw/permits/p_facil_report.aspx#Display https://talkbusiness.net/2023/07/waste-management-launches-35-million-rng-facility-in-springdale/ https://mediaroom.wm.com/wm-unveils-new-35-million-dollar-eco-vista-renewable-natural-gas-facility
A11: Altamont Landfill (Waste Management) | B11: OPERATIONAL | C11: Waste Management, Inc. | D11: 63798959 | F11: Alameda | G11: CA | H11: 40057 | I11: The Linde Group; High Mountain Fuels | J11: Creates LNG to fuel 300 garbage trucks; WM delivers it to their locations in the SF Bay Area mostly - Oakland, Livermore and San Leandro - with occasional deliveries to Castroville; generates electricity from landfill gas powered turbines and windmills. System's multi-step process includes compression, chilling, adsorption, and membranes to remove impurities, cleaned LFG is then cooled to -260 deg F to create 13,000 gal/day LNG for garbage trucks. | K11: 3.47 | L11: 6.504 | N11: =O11/(0.9*0.001*365) -> 611004.77 | O11: =R11*0.112194 -> 200715.07 | P11: VEHICLE FUEL (LOCAL) | Q11: Private | R11: 1789000 | S11: 4927500 | T11: Enough to "power LNG plant and 8000 homes annually". | U11: 221400 | W11: Yes | X11: https://www.wm.com/documents/pdfs-for-services-section/Case-studies-municipal/PSS_CsStdyAltamLndfllREVISE_rFjjg.pdfhttp://www.energy.ca.gov/2014publications/CEC-500-2014-054/CEC-500-2014-054.pdf http://altamontlandfill.wm.com/index.jsp http://energy-vision.org/case-studies/WM-Altamont-Profile.pdf https://sustainability.wm.com/downloads/WM_2020_SR_Executive_Summary.pdf
A12: New River RNG Project (New River Solid Waste Association, Fortistar Energy Group) | B12: OPERATIONAL | C12: Landfill, New River Solid Waste Association; upgrading, Fortistar; fuel distribution Opal (Fortistar subsidiary) | D12: 5408895 | F12: Union | G12: FL | H12: Summer 2022 | I12: Fortistar, New River Solid Waste Association | J12: 2500 SCFM LFG to RNG project | K12: =(2500*60*24)/1000000 -> 3.6 | L12: 1.92 | M12: 1.92 | N12: =K12*1000000*0.55 -> 1980000 | O12: =N12*(0.001*365*0.9) -> 650430 | P12: BOTH | Q12: Private | R12: =O12/0.112194 -> 5797368.8 | S12: 5100000 | U12: 35000 | W12: Yes | X12: https://nrswa.org/new-river-rng-project/#:~:text=The%20project%2C%20formally%20known%20as,Energy%2C%20a%20Fortistar%20portfolio%20company., https://www.epa.gov/sites/production/files/2019-05/documents/full-rfp_18-01_nrrl_lfg-to-cng.pdf , https://www.naturalgasintel.com/fortistar-partnering-on-florida-rng-project-to-fuel-ngvs/ https://www.environmentalleader.com/2020/12/florida-first-construction-begins-on-facility-that-will-convert-landfill-methane-to-renewable-natural-gas/ https://nrswa.org/new-river-rng-project/https://www.businesswire.com/news/home/20220810005219/en/OPAL-Fuels-Reports-Year-to-Date-2022-Results
A13: Live Oak Landfill | B13: OPERATIONAL | C13: Landfill, Waste Management, Inc. Upgrading System, AIr Liquide | D13: 16745404 | F13: DeKalb | G13: GA | H13: 39873 | I13: Jacoby Energy Development, Inc.; Atlanta Gas Light Company; Air Liquide; Energy Systems Group | J13: Creates high BTU RNG injected into the pipeline infrastructure. Also fuels 14 CNG sanitation trucks. Air Liquide process for upgrade to 2,300 scfm of high Btu gas; uses combination of pressure swing adsorption and membrane technology. "generating up to 1,500 MWh of renewable natural gas daily to be transported via pipeline" | K13: 2.38 | N13: =K13*0.55*1000000 -> 1309000 | O13: =N13*(0.001*365*0.9) -> 430006.5 | P13: PIPELINE (For vehicle/other) | Q13: No | R13: =O13/0.112194 -> 3832705 | U13: 618400 | W13: Yes | X13: http://www.renewableenergyworld.com/articles/2007/09/atlantas-live-oak-landfill-to-become-source-of-renewable-energy-50025.html http://jacobydevelopment.com/energy17.html https://industry.airliquide.us/air-liquide-acquires-renewable-natural-gas-plant-jacoby-energy https://www.energy.gov/sites/prod/files/2014/03/f10/june2012_biogas_workshop_anderson.pdf
A14: Dubuque Metro Landfill | B14: OPERATIONAL | C14: Dubuque Metropolitan Area Solid Waste Agency | D14: 4223369 | E14: 455 | F14: Dubuque | G14: IA | H14: Pipeline injection began Q4 2021. | I14: Dubuque Metropolitan Area Solid Waste Agency, Enerdyne | J14: Landfill gas capture system is being upgraded in 2019 from flaring to upgrading, for injection into interstate pipeline. Based on press releases on solid waste agency website, an agreement with Trillium fell through, the project is now being done by Enerdyne. Project to begin construction in Q4 2020 RNG production should begin Q3 2021, LFG flow to project ~750cfm. | K14: =(N14/0.55)/1000000 -> 1.2121212 | N14: =O14/(0.001*365*0.9) -> 666666.67 | O14: =600*365 -> 219000 | P14: PIPELINE (For vehicle/other) | R14: =O14/0.112194 -> 1951976 | X14: https://www.telegraphherald.com/news/tri-state/article_1894f2e2-0523-5340-9caf-9ed22979c8cd.html http://landfillgroup.com/projects/dubuque-gas-producers-llc/
A15: Loess Hills Regional Sanitary Landfill | B15: OPERATIONAL | C15: Iowa Waste Services | D15: 4849617 | E15: ~1780 | F15: Mills | G15: IA | H15: 45170 | I15: Waste Connections, ESI | J15: Landfill gas from 76 gas wells scattered across the landfill is processed on-site, then goes through an interconnect station owned by Kinder Morgan and on to a BP gas pipeline. Initially, the facility will process 1,500 cfm landfill gas into RNG. Landfill officials estimate that within 15 years, the production rate will increase to 4,000 cfm, generating enough renewable energy to meet the needs of nearly 14,000 Iowa homes per year. Project was $35 million and two years in the making. | K15: 2.16 | N15: 1188000 | O15: 390258 | P15: PIPELINE (For vehicle/other) | X15: https://www.opinion-tribune.com/news/mills-county-landfill-gas-being-processed-renewable-energy https://www.iawaste.com https://www.linkedin.com/posts/energyneeringsolutions_esi-landfill-biogas-activity-7084881980730863616-0Ksg?trk=public_profile_like_view
A16: Milam Recycling and Disposal Facility (Waste Management) | B16: OPERATIONAL | C16: Waste Management, Inc. | D16: 29903905 | F16: St. Clair | G16: IL | H16: 42073 | I16: WM Renewable Energy, LLC, Air Liquide | J16: Facility designed to process 3,500 cfm LF. Gas is transported via natural gas pipelines to WM’s CNG fueling stations and CNG trucks. Upgrading equipment: CO2/siloxane: Air Liquide membrane with carbon polisher. Nitrogen/Oxygen: ARI PSA. | K16: 3.6 | L16: 4.556 | M16: 1.186 | N16: 1600000 | O16: 576000 | P16: PIPELINE (For vehicle/other) | Q16: No | R16: =O16/0.112194 -> 5133964.4 | S16: 5486000 | T16: 2.4 MW for RNG plant demand, none exported to grid. Three Cat 3516 engines running on natural gas | U16: 310000 | W16: Yes | X16: https://www.wmsolutions.com/locations/details/id/31 https://waste-management-world.com/a/waste-management-opens-19m-landfill-gas-grid-injection-facility-in-illinois https://sustainability.wm.com/downloads/WM_2020_SR_Executive_Summary.pdf
A17: Will County Renewable Natural Gas Facility at Prairie View Landfill | B17: OPERATIONAL | C17: Will County (WM Operating landfill, maybe not the RNG facility) | D17: 10510812 | F17: Will | G17: IL | H17: October 2022 | I17: Will County; (WM may operate, or a different third party, unknown as of July 2021) | J17: Conversion of LFG to electricity project to RNG. County has 10 year agreement with US Venture to buy RNG from the facility to sell as vehicle fuel. Estimated costs of upgrading system and pipeline $46 million. | K17: 4.252 | L17: 4.252 | M17: 2.102 | N17: =(O17/5.5)*10 -> 1766545.5 | O17: 971600 | P17: PIPELINE (For vehicle/other) | Q17: No | R17: =7700000*1.14 -> 8778000 | U17: 40,000-61,500 | X17: http://biomassmagazine.com/articles/17747/agreement-signed-for-illinois-rng-project https://www.wjol.com/will-county-board-approves-renewable-natural-gas-plant/ http://willcountyil.iqm2.com/Citizens/FileOpen.aspx?Type=1&ID=3814 https://www.wjol.com/will-county-celebrates-ribbon-cutting-at-new-renewable-natural-gas-plant/
A18: WM Twin Bridges Landfill | B18: OPERATIONAL | C18: Landfill Waste Mangement; upgrading project, Kinder Morgan | D18: 28621989 | F18: Hendricks | G18: IN | H18: 45107 | I18: Kinetrex | J18: Project converts approximately 8.64 mmscfd of landfill gas to pipeline quality. The construction also included a 5-mile pipeline lateral to transport the RNG to the to a nearby third-party transmission pipeline. Begin monetizing RINs in Q3 2023. | L18: 8.64 | N18: =(L18*1000000)*0.55 -> 4752000 | O18: =N18*(0.001*365*0.9) -> 1561032 | P18: PIPELINE (For vehicle/other) | R18: =O18/0.112194 -> 13913685 | X18: https://www.wmsolutions.com/pdf-tracker/index/id/63/campaignType/28 http://s24.q4cdn.com/126708163/files/doc_presentations/2021/09/September-2021-Investor-Presentation-old.pdf https://www.nasdaq.com/articles/kinder-morgan-kmi-affiliate-starts-3-rng-plants-construction-2021-10-05 https://www.kindermorgan.com/Operations/Projects/Kinetrex-Landfill-Based-RNG-Facilities-Project
